Workbook
Name Slicer_Country1: #N/A
Name Slicer_Datekey_Opening_corrected_year: #N/A

Sheet Raw Data
A1: RestaurantID | B1: RestaurantName | C1: CountryCode | D1: Country | E1: City | F1: Address | G1: Cuisines | H1: Currency | I1: Has_Table_booking | J1: Has_Online_delivery | K1: Price_range | L1: Votes | M1: Average_Cost_for_two | N1: Rating | O1: Datekey_Opening_corrected(year) | P1: datekey_opening_corrected(month) | Q1: datekey_opening_corrected(day) | R1: datekey_opening_corrected | S1: Price | T1: CONVERSION FACTOR | U1: AVERAGE_COST_OF_TWO(INR)
A2: 18435314 | B2: Punjabi's Veg Grill | C2: 1 | D2: =VLOOKUP('Raw Data'!$C2,'country description'!$A$2:$B$16,2,0) -> India | E2: New Delhi | F2: 13/288 , 14 Block Gurudwra, Geeta Colony, New Delhi | G2: North Indian | H2: Indian Rupees(Rs.) | I2: No | J2: No | K2: 1 | L2: 0 | M2: 300 | N2: 1 | O2: 2013 | P2: 9 | Q2: 21 | R2: =DATE('Raw Data'!$O2,'Raw Data'!$P2,'Raw Data'!$Q2) -> 41538 | S2: =CONCATENATE(MID('Raw Data'!$H2,FIND("(",'Raw Data'!$H2)+1,FIND(")",'Raw Data'!$H2)-FIND("(",'Raw Data'!$H2)-1),"",'Raw Data'!$M2) -> Rs.300 | T2: =VLOOKUP(D2,$Y$4:$Z$18,2,0) -> 1 | U2: ='Raw Data'!$M2*'Raw Data'!$T2 -> 300
A3: 18378015 | B3: Tasty Tandoor | C3: 1 | D3: =VLOOKUP('Raw Data'!$C3,'country description'!$A$2:$B$16,2,0) -> India | E3: New Delhi | F3: 726/2, Jheel Khuranja, Geeta Colony, New Delhi | G3: North Indian | H3: Indian Rupees(Rs.) | I3: No | J3: No | K3: 1 | L3: 0 | M3: 200 | N3: 1 | O3: 2016 | P3: 9 | Q3: 10 | R3: =DATE('Raw Data'!$O3,'Raw Data'!$P3,'Raw Data'!$Q3) -> 42623 | S3: =CONCATENATE(MID('Raw Data'!$H3,FIND("(",'Raw Data'!$H3)+1,FIND(")",'Raw Data'!$H3)-FIND("(",'Raw Data'!$H3)-1),"",'Raw Data'!$M3) -> Rs.200 | T3: =VLOOKUP(D3,$Y$4:$Z$18,2,0) -> 1 | U3: ='Raw Data'!$M3*'Raw Data'!$T3 -> 200
A4: 18424905 | B4: Taste of Spice | C4: 1 | D4: =VLOOKUP('Raw Data'!$C4,'country description'!$A$2:$B$16,2,0) -> India | E4: New Delhi | F4: C-222, Lajpat Nagar 1, New Delhi | G4: North Indian | H4: Indian Rupees(Rs.) | I4: No | J4: Yes | K4: 1 | L4: 0 | M4: 400 | N4: 1 | O4: 2018 | P4: 9 | Q4: 25 | R4: =DATE('Raw Data'!$O4,'Raw Data'!$P4,'Raw Data'!$Q4) -> 43368 | S4: =CONCATENATE(MID('Raw Data'!$H4,FIND("(",'Raw Data'!$H4)+1,FIND(")",'Raw Data'!$H4)-FIND("(",'Raw Data'!$H4)-1),"",'Raw Data'!$M4) -> Rs.400 | T4: =VLOOKUP(D4,$Y$4:$Z$18,2,0) -> 1 | U4: ='Raw Data'!$M4*'Raw Data'!$T4 -> 400 | Y4: India | Z4: 1
A5: 18180072 | B5: Kolcata Bengali Dhaba | C5: 1 | D5: =VLOOKUP('Raw Data'!$C5,'country description'!$A$2:$B$16,2,0) -> India | E5: New Delhi | F5: Gali 7, Mahipalpur, New Delhi | G5: North Indian | H5: Indian Rupees(Rs.) | I5: No | J5: No | K5: 1 | L5: 0 | M5: 100 | N5: 1 | O5: 2018 | P5: 9 | Q5: 6 | R5: =DATE('Raw Data'!$O5,'Raw Data'!$P5,'Raw Data'!$Q5) -> 43349 | S5: =CONCATENATE(MID('Raw Data'!$H5,FIND("(",'Raw Data'!$H5)+1,FIND(")",'Raw Data'!$H5)-FIND("(",'Raw Data'!$H5)-1),"",'Raw Data'!$M5) -> Rs.100 | T5: =VLOOKUP(D5,$Y$4:$Z$18,2,0) -> 1 | U5: ='Raw Data'!$M5*'Raw Data'!$T5 -> 100 | Y5: United States of America | Z5: 87.392
A6: 18415377 | B6: Sunil Punjabi Dhaba | C6: 1 | D6: =VLOOKUP('Raw Data'!$C6,'country description'!$A$2:$B$16,2,0) -> India | E6: New Delhi | F6: Main Vasant Kunj Road, Mahipalpur, New Delhi | G6: North Indian | H6: Indian Rupees(Rs.) | I6: No | J6: No | K6: 1 | L6: 0 | M6: 150 | N6: 1 | O6: 2013 | P6: 9 | Q6: 17 | R6: =DATE('Raw Data'!$O6,'Raw Data'!$P6,'Raw Data'!$Q6) -> 41534 | S6: =CONCATENATE(MID('Raw Data'!$H6,FIND("(",'Raw Data'!$H6)+1,FIND(")",'Raw Data'!$H6)-FIND("(",'Raw Data'!$H6)-1),"",'Raw Data'!$M6) -> Rs.150 | T6: =VLOOKUP(D6,$Y$4:$Z$18,2,0) -> 1 | U6: ='Raw Data'!$M6*'Raw Data'!$T6 -> 150 | Y6: United Kingdom | Z6: 111.1
A7: 18421485 | B7: Bikaner Restaurant | C7: 1 | D7: =VLOOKUP('Raw Data'!$C7,'country description'!$A$2:$B$16,2,0) -> India | E7: New Delhi | F7: Shop 264, Near Hakikat Nagar, Mukherjee Nagar, New Delhi | G7: North Indian | H7: Indian Rupees(Rs.) | I7: No | J7: No | K7: 1 | L7: 0 | M7: 100 | N7: 1 | O7: 2018 | P7: 9 | Q7: 3 | R7: =DATE('Raw Data'!$O7,'Raw Data'!$P7,'Raw Data'!$Q7) -> 43346 | S7: =CONCATENATE(MID('Raw Data'!$H7,FIND("(",'Raw Data'!$H7)+1,FIND(")",'Raw Data'!$H7)-FIND("(",'Raw Data'!$H7)-1),"",'Raw Data'!$M7) -> Rs.100 | T7: =VLOOKUP(D7,$Y$4:$Z$18,2,0) -> 1 | U7: ='Raw Data'!$M7*'Raw Data'!$T7 -> 100 | Y7: Singapore | Z7: 64.99
A8: 312413 | B8: Just In | C8: 1 | D8: =VLOOKUP('Raw Data'!$C8,'country description'!$A$2:$B$16,2,0) -> India | E8: New Delhi | F8: G-103, Vardhaman Mall, Mukherjee Nagar, New Delhi | G8: North Indian | H8: Indian Rupees(Rs.) | I8: No | J8: No | K8: 1 | L8: 0 | M8: 200 | N8: 1 | O8: 2011 | P8: 9 | Q8: 16 | R8: =DATE('Raw Data'!$O8,'Raw Data'!$P8,'Raw Data'!$Q8) -> 40802 | S8: =CONCATENATE(MID('Raw Data'!$H8,FIND("(",'Raw Data'!$H8)+1,FIND(")",'Raw Data'!$H8)-FIND("(",'Raw Data'!$H8)-1),"",'Raw Data'!$M8) -> Rs.200 | T8: =VLOOKUP(D8,$Y$4:$Z$18,2,0) -> 1 | U8: ='Raw Data'!$M8*'Raw Data'!$T8 -> 200 | Y8: Canada | Z8: 60.46
A9: 303497 | B9: Shri Shyam Ji Shudh Shakahari Bhojnalaya | C9: 1 | D9: =VLOOKUP('Raw Data'!$C9,'country description'!$A$2:$B$16,2,0) -> India | E9: New Delhi | F9: Khaira Mod, Najafgarh, New Delhi | G9: North Indian | H9: Indian Rupees(Rs.) | I9: No | J9: No | K9: 1 | L9: 0 | M9: 150 | N9: 1 | O9: 2014 | P9: 9 | Q9: 21 | R9: =DATE('Raw Data'!$O9,'Raw Data'!$P9,'Raw Data'!$Q9) -> 41903 | S9: =CONCATENATE(MID('Raw Data'!$H9,FIND("(",'Raw Data'!$H9)+1,FIND(")",'Raw Data'!$H9)-FIND("(",'Raw Data'!$H9)-1),"",'Raw Data'!$M9) -> Rs.150 | T9: =VLOOKUP(D9,$Y$4:$Z$18,2,0) -> 1 | U9: ='Raw Data'!$M9*'Raw Data'!$T9 -> 150 | Y9: New Zealand | Z9: 49.06
A10: 18354644 | B10: Shree Bhojnalaya | C10: 1 | D10: =VLOOKUP('Raw Data'!$C10,'country description'!$A$2:$B$16,2,0) -> India | E10: New Delhi | F10: Sarai Julena, Near Red Light, New Friends Colony, New Delhi | G10: North Indian | H10: Indian Rupees(Rs.) | I10: No | J10: No | K10: 1 | L10: 0 | M10: 100 | N10: 1 | O10: 2012 | P10: 9 | Q10: 9 | R10: =DATE('Raw Data'!$O10,'Raw Data'!$P10,'Raw Data'!$Q10) -> 41161 | S10: =CONCATENATE(MID('Raw Data'!$H10,FIND("(",'Raw Data'!$H10)+1,FIND(")",'Raw Data'!$H10)-FIND("(",'Raw Data'!$H10)-1),"",'Raw Data'!$M10) -> Rs.100 | T10: =VLOOKUP(D10,$Y$4:$Z$18,2,0) -> 1 | U10: ='Raw Data'!$M10*'Raw Data'!$T10 -> 100 | Y10: United Arab Emirates | Z10: 23.78
A11: 18366001 | B11: Baba Ka Dhaba | C11: 1 | D11: =VLOOKUP('Raw Data'!$C11,'country description'!$A$2:$B$16,2,0) -> India | E11: New Delhi | F11: WZ-425, Main Road, Palam Colony, Opposite Railway Crossing, Palam, New Delhi | G11: North Indian | H11: Indian Rupees(Rs.) | I11: No | J11: No | K11: 1 | L11: 0 | M11: 200 | N11: 1 | O11: 2014 | P11: 9 | Q11: 21 | R11: =DATE('Raw Data'!$O11,'Raw Data'!$P11,'Raw Data'!$Q11) -> 41903 | S11: =CONCATENATE(MID('Raw Data'!$H11,FIND("(",'Raw Data'!$H11)+1,FIND(")",'Raw Data'!$H11)-FIND("(",'Raw Data'!$H11)-1),"",'Raw Data'!$M11) -> Rs.200 | T11: =VLOOKUP(D11,$Y$4:$Z$18,2,0) -> 1 | U11: ='Raw Data'!$M11*'Raw Data'!$T11 -> 200 | Y11: Brazil | Z11: 14.8512
A12: 18486845 | B12: Kaka Da Dhaba | C12: 1 | D12: =VLOOKUP('Raw Data'!$C12,'country description'!$A$2:$B$16,2,0) -> India | E12: New Delhi | F12: R.K. Puram Sector 12, R K Puram, New Delhi | G12: North Indian | H12: Indian Rupees(Rs.) | I12: No | J12: No | K12: 1 | L12: 0 | M12: 100 | N12: 1 | O12: 2012 | P12: 9 | Q12: 24 | R12: =DATE('Raw Data'!$O12,'Raw Data'!$P12,'Raw Data'!$Q12) -> 41176 | S12: =CONCATENATE(MID('Raw Data'!$H12,FIND("(",'Raw Data'!$H12)+1,FIND(")",'Raw Data'!$H12)-FIND("(",'Raw Data'!$H12)-1),"",'Raw Data'!$M12) -> Rs.100 | T12: =VLOOKUP(D12,$Y$4:$Z$18,2,0) -> 1 | U12: ='Raw Data'!$M12*'Raw Data'!$T12 -> 100 | Y12: Australia | Z12: 54.22
A13: 18424202 | B13: Famous Parantha and Poori Sabzi | C13: 1 | D13: =VLOOKUP('Raw Data'!$C13,'country description'!$A$2:$B$16,2,0) -> India | E13: New Delhi | F13: 44, Gali Number 1, Block A, New Ashok Nagar, Vasundhara Enclave, New Delhi | G13: North Indian | H13: Indian Rupees(Rs.) | I13: No | J13: No | K13: 1 | L13: 0 | M13: 50 | N13: 1 | O13: 2014 | P13: 9 | Q13: 20 | R13: =DATE('Raw Data'!$O13,'Raw Data'!$P13,'Raw Data'!$Q13) -> 41902 | S13: =CONCATENATE(MID('Raw Data'!$H13,FIND("(",'Raw Data'!$H13)+1,FIND(")",'Raw Data'!$H13)-FIND("(",'Raw Data'!$H13)-1),"",'Raw Data'!$M13) -> Rs.50 | T13: =VLOOKUP(D13,$Y$4:$Z$18,2,0) -> 1 | U13: ='Raw Data'!$M13*'Raw Data'!$T13 -> 50 | Y13: Turkey | Z13: 2.39
A14: 18472678 | B14: Garam Masala | C14: 1 | D14: =VLOOKUP('Raw Data'!$C14,'country description'!$A$2:$B$16,2,0) -> India | E14: New Delhi | F14: 1002, Gurudwara Road, Kotla Mubarakpur, Defence Colony, New Delhi | G14: North Indian | H14: Indian Rupees(Rs.) | I14: No | J14: No | K14: 1 | L14: 0 | M14: 300 | N14: 1 | O14: 2013 | P14: 8 | Q14: 10 | R14: =DATE('Raw Data'!$O14,'Raw Data'!$P14,'Raw Data'!$Q14) -> 41496 | S14: =CONCATENATE(MID('Raw Data'!$H14,FIND("(",'Raw Data'!$H14)+1,FIND(")",'Raw Data'!$H14)-FIND("(",'Raw Data'!$H14)-1),"",'Raw Data'!$M14) -> Rs.300 | T14: =VLOOKUP(D14,$Y$4:$Z$18,2,0) -> 1 | U14: ='Raw Data'!$M14*'Raw Data'!$T14 -> 300 | Y14: Qatar | Z14: 24.05
A15: 18209806 | B15: Zaika-E-Chaap Express | C15: 1 | D15: =VLOOKUP('Raw Data'!$C15,'country description'!$A$2:$B$16,2,0) -> India | E15: New Delhi | F15: Near Police Chowki, Golchakkar, R Block, Dilshad Garden, New Delhi | G15: North Indian | H15: Indian Rupees(Rs.) | I15: No | J15: No | K15: 1 | L15: 0 | M15: 250 | N15: 1 | O15: 2010 | P15: 8 | Q15: 20 | R15: =DATE('Raw Data'!$O15,'Raw Data'!$P15,'Raw Data'!$Q15) -> 40410 | S15: =CONCATENATE(MID('Raw Data'!$H15,FIND("(",'Raw Data'!$H15)+1,FIND(")",'Raw Data'!$H15)-FIND("(",'Raw Data'!$H15)-1),"",'Raw Data'!$M15) -> Rs.250 | T15: =VLOOKUP(D15,$Y$4:$Z$18,2,0) -> 1 | U15: ='Raw Data'!$M15*'Raw Data'!$T15 -> 250 | Y15: South Africa | Z15: 4.7
... A18: 7362 | B18: Vaishno Da Dhaba | C18: 1 | D18: =VLOOKUP('Raw Data'!$C18,'country description'!$A$2:$B$16,2,0) -> India | E18: New Delhi | F18: Badam Singh Market, NH 8, Rangpuri, Mahipalpur, New Delhi | G18: North Indian | H18: Indian Rupees(Rs.) | I18: No | J18: No | K18: 1 | L18: 0 | M18: 200 | N18: 1 | O18: 2010 | P18: 8 | Q18: 24 | R18: =DATE('Raw Data'!$O18,'Raw Data'!$P18,'Raw Data'!$Q18) -> 40414 | S18: =CONCATENATE(MID('Raw Data'!$H18,FIND("(",'Raw Data'!$H18)+1,FIND(")",'Raw Data'!$H18)-FIND("(",'Raw Data'!$H18)-1),"",'Raw Data'!$M18) -> Rs.200 | T18: =VLOOKUP(D18,$Y$4:$Z$18,2,0) -> 1 | U18: ='Raw Data'!$M18*'Raw Data'!$T18 -> 200 | Y18: Indonesia | Z18: 0.005301
A19: 18466400 | B19: Desi Thaat Amritsari Naan | C19: 1 | D19: =VLOOKUP('Raw Data'!$C19,'country description'!$A$2:$B$16,2,0) -> India | E19: New Delhi | F19: 14/1, Indira Vikas Colony, Near Nirankari School, Mukherjee Nagar, New Delhi | G19: North Indian | H19: Indian Rupees(Rs.) | I19: No | J19: No | K19: 1 | L19: 0 | M19: 300 | N19: 1 | O19: 2015 | P19: 8 | Q19: 13 | R19: =DATE('Raw Data'!$O19,'Raw Data'!$P19,'Raw Data'!$Q19) -> 42229 | S19: =CONCATENATE(MID('Raw Data'!$H19,FIND("(",'Raw Data'!$H19)+1,FIND(")",'Raw Data'!$H19)-FIND("(",'Raw Data'!$H19)-1),"",'Raw Data'!$M19) -> Rs.300 | T19: =VLOOKUP(D19,$Y$4:$Z$18,2,0) -> 1 | U19: ='Raw Data'!$M19*'Raw Data'!$T19 -> 300
A20: 18361779 | B20: Haryana Bhojnalaya | C20: 1 | D20: =VLOOKUP('Raw Data'!$C20,'country description'!$A$2:$B$16,2,0) -> India | E20: New Delhi | F20: G 26, Vardhman Central Mall, Nehru Vihar, Mukherjee Nagar, New Delhi | G20: North Indian | H20: Indian Rupees(Rs.) | I20: No | J20: No | K20: 1 | L20: 0 | M20: 100 | N20: 1 | O20: 2011 | P20: 8 | Q20: 24 | R20: =DATE('Raw Data'!$O20,'Raw Data'!$P20,'Raw Data'!$Q20) -> 40779 | S20: =CONCATENATE(MID('Raw Data'!$H20,FIND("(",'Raw Data'!$H20)+1,FIND(")",'Raw Data'!$H20)-FIND("(",'Raw Data'!$H20)-1),"",'Raw Data'!$M20) -> Rs.100 | T20: =VLOOKUP(D20,$Y$4:$Z$18,2,0) -> 1 | U20: ='Raw Data'!$M20*'Raw Data'!$T20 -> 100
A21: 18354672 | B21: Karol Bagh Ke Chhole Bhature | C21: 1 | D21: =VLOOKUP('Raw Data'!$C21,'country description'!$A$2:$B$16,2,0) -> India | E21: New Delhi | F21: Opposite Peer Baba, Gurgaon Road, Roshan Pura, Najafgarh, New Delhi | G21: North Indian | H21: Indian Rupees(Rs.) | I21: No | J21: No | K21: 1 | L21: 0 | M21: 150 | N21: 1 | O21: 2017 | P21: 8 | Q21: 21 | R21: =DATE('Raw Data'!$O21,'Raw Data'!$P21,'Raw Data'!$Q21) -> 42968 | S21: =CONCATENATE(MID('Raw Data'!$H21,FIND("(",'Raw Data'!$H21)+1,FIND(")",'Raw Data'!$H21)-FIND("(",'Raw Data'!$H21)-1),"",'Raw Data'!$M21) -> Rs.150 | T21: =VLOOKUP(D21,$Y$4:$Z$18,2,0) -> 1 | U21: ='Raw Data'!$M21*'Raw Data'!$T21 -> 150
A22: 18464641 | B22: Bala Ji Rasoi | C22: 1 | D22: =VLOOKUP('Raw Data'!$C22,'country description'!$A$2:$B$16,2,0) -> India | E22: New Delhi | F22: A-18, Naresh Park, Najafgarh Road, Nangloi, New Delhi | G22: North Indian | H22: Indian Rupees(Rs.) | I22: No | J22: No | K22: 1 | L22: 0 | M22: 350 | N22: 1 | O22: 2012 | P22: 8 | Q22: 9 | R22: =DATE('Raw Data'!$O22,'Raw Data'!$P22,'Raw Data'!$Q22) -> 41130 | S22: =CONCATENATE(MID('Raw Data'!$H22,FIND("(",'Raw Data'!$H22)+1,FIND(")",'Raw Data'!$H22)-FIND("(",'Raw Data'!$H22)-1),"",'Raw Data'!$M22) -> Rs.350 | T22: =VLOOKUP(D22,$Y$4:$Z$18,2,0) -> 1 | U22: ='Raw Data'!$M22*'Raw Data'!$T22 -> 350 | Y22: =AVERAGEIF(J:J,"Yes",N:N) -> 3.2880049
A23: 18312665 | B23: Best Chicken Corner | C23: 1 | D23: =VLOOKUP('Raw Data'!$C23,'country description'!$A$2:$B$16,2,0) -> India | E23: New Delhi | F23: Main Rohtak Road, Near Sutan Puri More, Opposite Metro Pillar 373, Nangloi, New Delhi | G23: North Indian | H23: Indian Rupees(Rs.) | I23: No | J23: No | K23: 2 | L23: 0 | M23: 650 | N23: 1 | O23: 2010 | P23: 8 | Q23: 4 | R23: =DATE('Raw Data'!$O23,'Raw Data'!$P23,'Raw Data'!$Q23) -> 40394 | S23: =CONCATENATE(MID('Raw Data'!$H23,FIND("(",'Raw Data'!$H23)+1,FIND(")",'Raw Data'!$H23)-FIND("(",'Raw Data'!$H23)-1),"",'Raw Data'!$M23) -> Rs.650 | T23: =VLOOKUP(D23,$Y$4:$Z$18,2,0) -> 1 | U23: ='Raw Data'!$M23*'Raw Data'!$T23 -> 650
A24: 18312572 | B24: Avatar Da Dhaba | C24: 1 | D24: =VLOOKUP('Raw Data'!$C24,'country description'!$A$2:$B$16,2,0) -> India | E24: New Delhi | F24: Ring Road Narayna, Opp Dharamshala, Naraina, New Delhi | G24: North Indian | H24: Indian Rupees(Rs.) | I24: No | J24: No | K24: 1 | L24: 0 | M24: 200 | N24: 1 | O24: 2017 | P24: 8 | Q24: 13 | R24: =DATE('Raw Data'!$O24,'Raw Data'!$P24,'Raw Data'!$Q24) -> 42960 | S24: =CONCATENATE(MID('Raw Data'!$H24,FIND("(",'Raw Data'!$H24)+1,FIND(")",'Raw Data'!$H24)-FIND("(",'Raw Data'!$H24)-1),"",'Raw Data'!$M24) -> Rs.200 | T24: =VLOOKUP(D24,$Y$4:$Z$18,2,0) -> 1 | U24: ='Raw Data'!$M24*'Raw Data'!$T24 -> 200
A25: 18349241 | B25: Curry Man | C25: 1 | D25: =VLOOKUP('Raw Data'!$C25,'country description'!$A$2:$B$16,2,0) -> India | E25: New Delhi | F25: G-181, Naraina Vihar, Naraina, New Delhi | G25: North Indian | H25: Indian Rupees(Rs.) | I25: No | J25: No | K25: 1 | L25: 0 | M25: 200 | N25: 1 | O25: 2016 | P25: 8 | Q25: 6 | R25: =DATE('Raw Data'!$O25,'Raw Data'!$P25,'Raw Data'!$Q25) -> 42588 | S25: =CONCATENATE(MID('Raw Data'!$H25,FIND("(",'Raw Data'!$H25)+1,FIND(")",'Raw Data'!$H25)-FIND("(",'Raw Data'!$H25)-1),"",'Raw Data'!$M25) -> Rs.200 | T25: =VLOOKUP(D25,$Y$4:$Z$18,2,0) -> 1 | U25: ='Raw Data'!$M25*'Raw Data'!$T25 -> 200
A26: 18355121 | B26: Delicious Eating Corner | C26: 1 | D26: =VLOOKUP('Raw Data'!$C26,'country description'!$A$2:$B$16,2,0) -> India | E26: New Delhi | F26: Shop 2 & 3, DDA Mini Market, Opposite Wine Shop, Nehru Place, New Delhi | G26: North Indian | H26: Indian Rupees(Rs.) | I26: No | J26: No | K26: 1 | L26: 0 | M26: 400 | N26: 1 | O26: 2013 | P26: 8 | Q26: 24 | R26: =DATE('Raw Data'!$O26,'Raw Data'!$P26,'Raw Data'!$Q26) -> 41510 | S26: =CONCATENATE(MID('Raw Data'!$H26,FIND("(",'Raw Data'!$H26)+1,FIND(")",'Raw Data'!$H26)-FIND("(",'Raw Data'!$H26)-1),"",'Raw Data'!$M26) -> Rs.400 | T26: =VLOOKUP(D26,$Y$4:$Z$18,2,0) -> 1 | U26: ='Raw Data'!$M26*'Raw Data'!$T26 -> 400
A27: 18289272 | B27: Massi's Kitchen | C27: 1 | D27: =VLOOKUP('Raw Data'!$C27,'country description'!$A$2:$B$16,2,0) -> India | E27: New Delhi | F27: 494, Ganesh Nagar 2, Pandav Nagar, New Delhi | G27: North Indian | H27: Indian Rupees(Rs.) | I27: No | J27: No | K27: 1 | L27: 0 | M27: 200 | N27: 1 | O27: 2014 | P27: 8 | Q27: 6 | R27: =DATE('Raw Data'!$O27,'Raw Data'!$P27,'Raw Data'!$Q27) -> 41857 | S27: =CONCATENATE(MID('Raw Data'!$H27,FIND("(",'Raw Data'!$H27)+1,FIND(")",'Raw Data'!$H27)-FIND("(",'Raw Data'!$H27)-1),"",'Raw Data'!$M27) -> Rs.200 | T27: =VLOOKUP(D27,$Y$4:$Z$18,2,0) -> 1 | U27: ='Raw Data'!$M27*'Raw Data'!$T27 -> 200
A28: 18449949 | B28: Roll Junction | C28: 1 | D28: =VLOOKUP('Raw Data'!$C28,'country description'!$A$2:$B$16,2,0) -> India | E28: New Delhi | F28: F 205 & 206, Near Akshardham Temple, Pandav Nagar, New Delhi | G28: North Indian | H28: Indian Rupees(Rs.) | I28: No | J28: No | K28: 1 | L28: 0 | M28: 150 | N28: 1 | O28: 2010 | P28: 8 | Q28: 8 | R28: =DATE('Raw Data'!$O28,'Raw Data'!$P28,'Raw Data'!$Q28) -> 40398 | S28: =CONCATENATE(MID('Raw Data'!$H28,FIND("(",'Raw Data'!$H28)+1,FIND(")",'Raw Data'!$H28)-FIND("(",'Raw Data'!$H28)-1),"",'Raw Data'!$M28) -> Rs.150 | T28: =VLOOKUP(D28,$Y$4:$Z$18,2,0) -> 1 | U28: ='Raw Data'!$M28*'Raw Data'!$T28 -> 150
A29: 18451571 | B29: Amritsari Naan | C29: 1 | D29: =VLOOKUP('Raw Data'!$C29,'country description'!$A$2:$B$16,2,0) -> India | E29: New Delhi | F29: QU-1, Pitampura, New Delhi | G29: North Indian | H29: Indian Rupees(Rs.) | I29: No | J29: No | K29: 1 | L29: 0 | M29: 200 | N29: 1 | O29: 2016 | P29: 8 | Q29: 3 | R29: =DATE('Raw Data'!$O29,'Raw Data'!$P29,'Raw Data'!$Q29) -> 42585 | S29: =CONCATENATE(MID('Raw Data'!$H29,FIND("(",'Raw Data'!$H29)+1,FIND(")",'Raw Data'!$H29)-FIND("(",'Raw Data'!$H29)-1),"",'Raw Data'!$M29) -> Rs.200 | T29: =VLOOKUP(D29,$Y$4:$Z$18,2,0) -> 1 | U29: ='Raw Data'!$M29*'Raw Data'!$T29 -> 200
A30: 18446496 | B30: Parantha on Call | C30: 1 | D30: =VLOOKUP('Raw Data'!$C30,'country description'!$A$2:$B$16,2,0) -> India | E30: New Delhi | F30: Geeta Colony, New Delhi | G30: North Indian | H30: Indian Rupees(Rs.) | I30: No | J30: No | K30: 1 | L30: 0 | M30: 100 | N30: 1 | O30: 2018 | P30: 7 | Q30: 26 | R30: =DATE('Raw Data'!$O30,'Raw Data'!$P30,'Raw Data'!$Q30) -> 43307 | S30: =CONCATENATE(MID('Raw Data'!$H30,FIND("(",'Raw Data'!$H30)+1,FIND(")",'Raw Data'!$H30)-FIND("(",'Raw Data'!$H30)-1),"",'Raw Data'!$M30) -> Rs.100 | T30: =VLOOKUP(D30,$Y$4:$Z$18,2,0) -> 1 | U30: ='Raw Data'!$M30*'Raw Data'!$T30 -> 100
A31: 18357972 | B31: Satnaam Foods | C31: 1 | D31: =VLOOKUP('Raw Data'!$C31,'country description'!$A$2:$B$16,2,0) -> India | E31: New Delhi | F31: 101 A, Pratap Nagar, Mayur Vihar Phase 1, New Delhi | G31: North Indian | H31: Indian Rupees(Rs.) | I31: No | J31: No | K31: 1 | L31: 0 | M31: 300 | N31: 1 | O31: 2011 | P31: 7 | Q31: 18 | R31: =DATE('Raw Data'!$O31,'Raw Data'!$P31,'Raw Data'!$Q31) -> 40742 | S31: =CONCATENATE(MID('Raw Data'!$H31,FIND("(",'Raw Data'!$H31)+1,FIND(")",'Raw Data'!$H31)-FIND("(",'Raw Data'!$H31)-1),"",'Raw Data'!$M31) -> Rs.300 | T31: =VLOOKUP(D31,$Y$4:$Z$18,2,0) -> 1 | U31: ='Raw Data'!$M31*'Raw Data'!$T31 -> 300
A32: 18375383 | B32: The Deshi Bites | C32: 1 | D32: =VLOOKUP('Raw Data'!$C32,'country description'!$A$2:$B$16,2,0) -> India | E32: New Delhi | F32: SFS Flats, Near Pocket-C, Mayur Vihar Phase 3, New Delhi | G32: North Indian | H32: Indian Rupees(Rs.) | I32: No | J32: No | K32: 2 | L32: 0 | M32: 500 | N32: 1 | O32: 2018 | P32: 7 | Q32: 28 | R32: =DATE('Raw Data'!$O32,'Raw Data'!$P32,'Raw Data'!$Q32) -> 43309 | S32: =CONCATENATE(MID('Raw Data'!$H32,FIND("(",'Raw Data'!$H32)+1,FIND(")",'Raw Data'!$H32)-FIND("(",'Raw Data'!$H32)-1),"",'Raw Data'!$M32) -> Rs.500 | T32: =VLOOKUP(D32,$Y$4:$Z$18,2,0) -> 1 | U32: ='Raw Data'!$M32*'Raw Data'!$T32 -> 500
A33: 18236975 | B33: Syall Kotian Da Dhaba | C33: 1 | D33: =VLOOKUP('Raw Data'!$C33,'country description'!$A$2:$B$16,2,0) -> India | E33: New Delhi | F33: A-201, New, Moti Nagar, New Delhi | G33: North Indian | H33: Indian Rupees(Rs.) | I33: No | J33: No | K33: 2 | L33: 0 | M33: 500 | N33: 1 | O33: 2017 | P33: 7 | Q33: 22 | R33: =DATE('Raw Data'!$O33,'Raw Data'!$P33,'Raw Data'!$Q33) -> 42938 | S33: =CONCATENATE(MID('Raw Data'!$H33,FIND("(",'Raw Data'!$H33)+1,FIND(")",'Raw Data'!$H33)-FIND("(",'Raw Data'!$H33)-1),"",'Raw Data'!$M33) -> Rs.500 | T33: =VLOOKUP(D33,$Y$4:$Z$18,2,0) -> 1 | U33: ='Raw Data'!$M33*'Raw Data'!$T33 -> 500
A34: 18361767 | B34: Jyoti Dhaba | C34: 1 | D34: =VLOOKUP('Raw Data'!$C34,'country description'!$A$2:$B$16,2,0) -> India | E34: New Delhi | F34: Opposite Vardhman Central Mall, Nehru Vihar, Mukherjee Nagar, New Delhi | G34: North Indian | H34: Indian Rupees(Rs.) | I34: No | J34: No | K34: 1 | L34: 0 | M34: 150 | N34: 1 | O34: 2011 | P34: 7 | Q34: 4 | R34: =DATE('Raw Data'!$O34,'Raw Data'!$P34,'Raw Data'!$Q34) -> 40728 | S34: =CONCATENATE(MID('Raw Data'!$H34,FIND("(",'Raw Data'!$H34)+1,FIND(")",'Raw Data'!$H34)-FIND("(",'Raw Data'!$H34)-1),"",'Raw Data'!$M34) -> Rs.150 | T34: =VLOOKUP(D34,$Y$4:$Z$18,2,0) -> 1 | U34: ='Raw Data'!$M34*'Raw Data'!$T34 -> 150
... A9552: 6001980 | B9552: Timboo Cafe | C9552: 208 | D9552: =VLOOKUP('Raw Data'!$C9552,'country description'!$A$2:$B$16,2,0) -> Turkey | E9552: Ankara | F9552: Armada AVM, Kat -1, Eskiôehir Yolu, No 6, Yenimahalle, Ankara | G9552: Cafe | H9552: Turkish Lira(TL) | I9552: No | J9552: No | K9552: 3 | L9552: 134 | M9552: 70 | N9552: 4.2 | O9552: 2015 | P9552: 10 | Q9552: 4 | R9552: =DATE('Raw Data'!$O9552,'Raw Data'!$P9552,'Raw Data'!$Q9552) -> 42281 | S9552: =CONCATENATE(MID('Raw Data'!$H9552,FIND("(",'Raw Data'!$H9552)+1,FIND(")",'Raw Data'!$H9552)-FIND("(",'Raw Data'!$H9552)-1),"",'Raw Data'!$M9552) -> TL70 | T9552: =VLOOKUP(D9552,$Y$4:$Z$18,2,0) -> 2.39 | U9552: ='Raw Data'!$M9552*'Raw Data'!$T9552 -> 167.3

Sheet Dashboard
A1: Row Labels | B1: Average of Rating
A2: Australia | B2: 3.6583333
A3: Brazil | B3: 3.8466667
A4: Canada | B4: 3.575
A5: India | B5: 2.7705502
A6: Indonesia | B6: 4.2952381
A7: New Zealand | B7: 4.2625
A8: Philippines | B8: 4.4681818
A9: Qatar | B9: 4.06
A10: Singapore | B10: 3.575
A11: South Africa | B11: 4.21
A12: Sri Lanka | B12: 3.87
A13: Turkey | B13: 4.3
... A16: United States of America | B16: 4.0112903
FB20: Average of Rating
FB21: 2.8912679
A31: Row Labels | B31: Count of RestaurantID
A32: No | B32: 7100
A33: Yes | B33: 2451
A34: Grand Total | B34: 9551
A38: Row Labels | B38: Count of RestaurantID
A39: No | B39: 8393
A40: Yes | B40: 1158
AA45: a
A78: Row Labels | B78: Count of RestaurantID
A79: 2010 | B79: 1080
A80: 2011 | B80: 1098
A81: 2012 | B81: 1022
A82: 2013 | B82: 1061
A83: 2014 | B83: 1051
A84: 2015 | B84: 1024
A85: 2016 | B85: 1027
A86: 2017 | B86: 1086
A87: 2018 | B87: 1102
A142: Rating | B142: (Multiple Items)
A144: Row Labels | B144: Count of RestaurantID
A145: Cafe | B145: 36
A146: North Indian, Mughlai | B146: 29
A147: Italian | B147: 25
A148: North Indian | B148: 25
...

Sheet country description
A1: Country Code | B1: Country Name
A2: 1 | B2: India
A3: 14 | B3: Australia
A4: 30 | B4: Brazil
A5: 37 | B5: Canada
A6: 94 | B6: Indonesia
A7: 148 | B7: New Zealand
A8: 162 | B8: Philippines
A9: 166 | B9: Qatar
A10: 184 | B10: Singapore
A11: 189 | B11: South Africa
A12: 191 | B12: Sri Lanka
A13: 208 | B13: Turkey
... A16: 216 | B16: United States of America

Sheet que sheet
A1: Tasks
A2: Learners have to develop a dashboard to support the answers to the following questions and suggestions for places for newer restaurants.
A4: Objective Questions:
A6: 1. What is the total no. of tables present in the data?
A7: ans. | B7: 2
A8: 2. What is the total no. of attributes present in the data?
A9: ans. | B9: =COLUMNS(A:T)+COLUMNS('[1]country description'!A:B) -> 22
A10: 3. How many categorical columns are there in the data? [Search about categorical and continuous data, and try to answer this question]
A11: ans. | B11: 13
A12: 4. The data consists of some inconsistent and missing values so ensure that the data used for further analysis is cleaned.
A13: 5. Using the LookUp functions, fill up the countries in the original data using the country code.
A14: 6. Create a table to represent the number of restaurants opened in each country.
A15: 7. Also, the management wants to look at the number of restaurants opened each year, so provide them with something here.
A16: 8. What is the total number of restaurants in India in the price range of 4?
A17: 9. What is the average number of voters for the restaurants in each country according to the data?
A18: 10. Calculate the average rating for all the restaurants that have price_range < 4 and provide online delivery. Use only the “IF” function, Logical Operators, and Aggregation functions to solve this problem. [Note: Don’t use Conditional aggregation in this question.]
A19: 11. Using Conditional formatting highlight the rows of restaurants that are located in the countries or cities that you’ve suggested to the management for opening new restaurants.
A20: 12. Create a new customized price column that consists of the abbreviation/symbol of the currency along with the Average_cost_for_two value. [Use string operations to do this task]
A21: 13. How can you create an array formula in Excel or Google Sheets to count the number of restaurants listed that do not offer online delivery, are in the lowest price range, and have an average cost for two people less than or equal to 250 Indian Rupees?
A23: (All the dashboard's pivot tables are present and hided in dashboard sheet for easily locating and to ensure proper dashboard look.)

Sheet objective answers
A1: 6)number of restaurants opened in each country.
A2: Countries | B2: Number of Restaurants
A3: Canada | B3: 4
A4: Qatar | B4: 20
A5: Singapore | B5: 20
A6: Sri Lanka | B6: 20
A7: Indonesia | B7: 21
A8: Philippines | B8: 22
A9: Australia | B9: 24
A10: Turkey | B10: 34
A11: New Zealand | B11: 40
A12: Brazil | B12: 60
A13: United Arab Emirates | B13: 60
A14: South Africa | B14: 60
... A17: India | B17: 8652
A25: 7)the number of restaurants opened each year
A26: Years | B26: No. of Restaurants
A27: 2010 | B27: 1080
A28: 2011 | B28: 1098
A29: 2012 | B29: 1022
A30: 2013 | B30: 1061
A31: 2014 | B31: 1051
A32: 2015 | B32: 1024
A33: 2016 | B33: 1027
A34: 2017 | B34: 1086
A35: 2018 | B35: 1102
A39: 8)Total number of restaurants in India in the price range of 4. | B39: =COUNTIFS('Raw Data'!K:K,"4",'Raw Data'!D:D,"India") -> 388
A45: 9)The average number of voters for the restaurants in each country according to the data.
A46: Countries | B46: Average of Votes
A47: Brazil | B47: 19.616667
A48: Singapore | B48: 31.9
A49: Canada | B49: 103
A50: Australia | B50: 111.41667
A51: India | B51: 137.21255
A52: Sri Lanka | B52: 146.45
A53: Qatar | B53: 163.8
A54: United Kingdom | B54: 205.4875
A55: New Zealand | B55: 243.025
A56: South Africa | B56: 315.16667
A57: Philippines | B57: 407.40909
...
